2024-11-16 18:25:06,316 - app - ERROR - Exception on /community/23 [GET]
Traceback (most recent call last):
  File "/home/juanant/Desktop/RaboDeToro-hub-1/RaboDeToroHub1venv/lib/python3.12/site-packages/flask/app.py", line 1473, in wsgi_app
    response = self.full_dispatch_request()
               ^^^^^^^^^^^^^^^^^^^^^^^^^^^^
  File "/home/juanant/Desktop/RaboDeToro-hub-1/RaboDeToroHub1venv/lib/python3.12/site-packages/flask/app.py", line 882, in full_dispatch_request
    rv = self.handle_user_exception(e)
         ^^^^^^^^^^^^^^^^^^^^^^^^^^^^^
  File "/home/juanant/Desktop/RaboDeToro-hub-1/RaboDeToroHub1venv/lib/python3.12/site-packages/flask_restful/__init__.py", line 298, in error_router
    return original_handler(e)
           ^^^^^^^^^^^^^^^^^^^
  File "/home/juanant/Desktop/RaboDeToro-hub-1/RaboDeToroHub1venv/lib/python3.12/site-packages/flask/app.py", line 880, in full_dispatch_request
    rv = self.dispatch_request()
         ^^^^^^^^^^^^^^^^^^^^^^^
  File "/home/juanant/Desktop/RaboDeToro-hub-1/RaboDeToroHub1venv/lib/python3.12/site-packages/flask/app.py", line 865, in dispatch_request
    return self.ensure_sync(self.view_functions[rule.endpoint])(**view_args)  # type: ignore[no-any-return]
           ^^^^^^^^^^^^^^^^^^^^^^^^^^^^^^^^^^^^^^^^^^^^^^^^^^^^^^^^^^^^^^^^^
  File "/home/juanant/Desktop/RaboDeToro-hub-1/RaboDeToroHub1venv/lib/python3.12/site-packages/flask_login/utils.py", line 290, in decorated_view
    return current_app.ensure_sync(func)(*args, **kwargs)
           ^^^^^^^^^^^^^^^^^^^^^^^^^^^^^^^^^^^^^^^^^^^^^^
  File "/home/juanant/Desktop/RaboDeToro-hub-1/app/modules/community/routes.py", line 33, in get_community
    return render_template('community/show.html', community=community)
           ^^^^^^^^^^^^^^^^^^^^^^^^^^^^^^^^^^^^^^^^^^^^^^^^^^^^^^^^^^^
  File "/home/juanant/Desktop/RaboDeToro-hub-1/RaboDeToroHub1venv/lib/python3.12/site-packages/flask/templating.py", line 150, in render_template
    return _render(app, template, context)
           ^^^^^^^^^^^^^^^^^^^^^^^^^^^^^^^
  File "/home/juanant/Desktop/RaboDeToro-hub-1/RaboDeToroHub1venv/lib/python3.12/site-packages/flask/templating.py", line 131, in _render
    rv = template.render(context)
         ^^^^^^^^^^^^^^^^^^^^^^^^
  File "/home/juanant/Desktop/RaboDeToro-hub-1/RaboDeToroHub1venv/lib/python3.12/site-packages/jinja2/environment.py", line 1304, in render
    self.environment.handle_exception()
  File "/home/juanant/Desktop/RaboDeToro-hub-1/RaboDeToroHub1venv/lib/python3.12/site-packages/jinja2/environment.py", line 939, in handle_exception
    raise rewrite_traceback_stack(source=source)
  File "/home/juanant/Desktop/RaboDeToro-hub-1/app/modules/community/templates/community/show.html", line 1, in top-level template code
    {% extends "base_template.html" %}
    ^^^^^^^^^^^^^^^^^^^^^^^^^
  File "/home/juanant/Desktop/RaboDeToro-hub-1/app/templates/base_template.html", line 184, in top-level template code
    {% block content %}{% endblock %}
    ^^^^^^^^^^^^^^^^^^^^^^^^^
  File "/home/juanant/Desktop/RaboDeToro-hub-1/app/modules/community/templates/community/show.html", line 9, in block 'content'
    <p>Users: {{ users.size() }}</p>
    ^^^^^^^^^^^^^^^^^^^^^^^^^
  File "/home/juanant/Desktop/RaboDeToro-hub-1/RaboDeToroHub1venv/lib/python3.12/site-packages/jinja2/environment.py", line 487, in getattr
    return getattr(obj, attribute)
           ^^^^^^^^^^^^^^^^^^^^^^^
jinja2.exceptions.UndefinedError: 'users' is undefined
2024-11-16 18:25:06,317 - app - ERROR - Internal Server Error: 500 Internal Server Error: The server encountered an internal error and was unable to complete your request. Either the server is overloaded or there is an error in the application.
2024-11-16 18:32:43,631 - app - ERROR - Exception on /community/23 [GET]
Traceback (most recent call last):
  File "/home/juanant/Desktop/RaboDeToro-hub-1/RaboDeToroHub1venv/lib/python3.12/site-packages/flask/app.py", line 1473, in wsgi_app
    response = self.full_dispatch_request()
               ^^^^^^^^^^^^^^^^^^^^^^^^^^^^
  File "/home/juanant/Desktop/RaboDeToro-hub-1/RaboDeToroHub1venv/lib/python3.12/site-packages/flask/app.py", line 882, in full_dispatch_request
    rv = self.handle_user_exception(e)
         ^^^^^^^^^^^^^^^^^^^^^^^^^^^^^
  File "/home/juanant/Desktop/RaboDeToro-hub-1/RaboDeToroHub1venv/lib/python3.12/site-packages/flask_restful/__init__.py", line 298, in error_router
    return original_handler(e)
           ^^^^^^^^^^^^^^^^^^^
  File "/home/juanant/Desktop/RaboDeToro-hub-1/RaboDeToroHub1venv/lib/python3.12/site-packages/flask/app.py", line 880, in full_dispatch_request
    rv = self.dispatch_request()
         ^^^^^^^^^^^^^^^^^^^^^^^
  File "/home/juanant/Desktop/RaboDeToro-hub-1/RaboDeToroHub1venv/lib/python3.12/site-packages/flask/app.py", line 865, in dispatch_request
    return self.ensure_sync(self.view_functions[rule.endpoint])(**view_args)  # type: ignore[no-any-return]
           ^^^^^^^^^^^^^^^^^^^^^^^^^^^^^^^^^^^^^^^^^^^^^^^^^^^^^^^^^^^^^^^^^
  File "/home/juanant/Desktop/RaboDeToro-hub-1/RaboDeToroHub1venv/lib/python3.12/site-packages/flask_login/utils.py", line 290, in decorated_view
    return current_app.ensure_sync(func)(*args, **kwargs)
           ^^^^^^^^^^^^^^^^^^^^^^^^^^^^^^^^^^^^^^^^^^^^^^
  File "/home/juanant/Desktop/RaboDeToro-hub-1/app/modules/community/routes.py", line 33, in get_community
    community_users = community_user_service.get_users_by_community(community_id=community.id)
                      ^^^^^^^^^^^^^^^^^^^^^^^^^^^^^^^^^^^^^^^^^^^^^^^^^^^^^^^^^^^^^^^^^^^^^^^^
  File "/home/juanant/Desktop/RaboDeToro-hub-1/app/modules/community/services.py", line 11, in get_users_by_community
    return self.repository.get_users_by_community(community_id)
           ^^^^^^^^^^^^^^^^^^^^^^^^^^^^^^^^^^^^^^^^^^^^^^^^^^^^
  File "/home/juanant/Desktop/RaboDeToro-hub-1/app/modules/community/repositories.py", line 11, in get_users_by_community
    return self.model.query.join(self.model.user).filter_by(community_id=community_id).all()
                                 ^^^^^^^^^^^^^^^
AttributeError: type object 'CommunityUser' has no attribute 'user'
2024-11-16 18:32:43,632 - app - ERROR - Internal Server Error: 500 Internal Server Error: The server encountered an internal error and was unable to complete your request. Either the server is overloaded or there is an error in the application.
2024-11-16 18:32:44,595 - app - ERROR - Exception on /community/23 [GET]
Traceback (most recent call last):
  File "/home/juanant/Desktop/RaboDeToro-hub-1/RaboDeToroHub1venv/lib/python3.12/site-packages/flask/app.py", line 1473, in wsgi_app
    response = self.full_dispatch_request()
               ^^^^^^^^^^^^^^^^^^^^^^^^^^^^
  File "/home/juanant/Desktop/RaboDeToro-hub-1/RaboDeToroHub1venv/lib/python3.12/site-packages/flask/app.py", line 882, in full_dispatch_request
    rv = self.handle_user_exception(e)
         ^^^^^^^^^^^^^^^^^^^^^^^^^^^^^
  File "/home/juanant/Desktop/RaboDeToro-hub-1/RaboDeToroHub1venv/lib/python3.12/site-packages/flask_restful/__init__.py", line 298, in error_router
    return original_handler(e)
           ^^^^^^^^^^^^^^^^^^^
  File "/home/juanant/Desktop/RaboDeToro-hub-1/RaboDeToroHub1venv/lib/python3.12/site-packages/flask/app.py", line 880, in full_dispatch_request
    rv = self.dispatch_request()
         ^^^^^^^^^^^^^^^^^^^^^^^
  File "/home/juanant/Desktop/RaboDeToro-hub-1/RaboDeToroHub1venv/lib/python3.12/site-packages/flask/app.py", line 865, in dispatch_request
    return self.ensure_sync(self.view_functions[rule.endpoint])(**view_args)  # type: ignore[no-any-return]
           ^^^^^^^^^^^^^^^^^^^^^^^^^^^^^^^^^^^^^^^^^^^^^^^^^^^^^^^^^^^^^^^^^
  File "/home/juanant/Desktop/RaboDeToro-hub-1/RaboDeToroHub1venv/lib/python3.12/site-packages/flask_login/utils.py", line 290, in decorated_view
    return current_app.ensure_sync(func)(*args, **kwargs)
           ^^^^^^^^^^^^^^^^^^^^^^^^^^^^^^^^^^^^^^^^^^^^^^
  File "/home/juanant/Desktop/RaboDeToro-hub-1/app/modules/community/routes.py", line 33, in get_community
    community_users = community_user_service.get_users_by_community(community_id=community.id)
                      ^^^^^^^^^^^^^^^^^^^^^^^^^^^^^^^^^^^^^^^^^^^^^^^^^^^^^^^^^^^^^^^^^^^^^^^^
  File "/home/juanant/Desktop/RaboDeToro-hub-1/app/modules/community/services.py", line 11, in get_users_by_community
    return self.repository.get_users_by_community(community_id)
           ^^^^^^^^^^^^^^^^^^^^^^^^^^^^^^^^^^^^^^^^^^^^^^^^^^^^
  File "/home/juanant/Desktop/RaboDeToro-hub-1/app/modules/community/repositories.py", line 11, in get_users_by_community
    return self.model.query.join(self.model.user).filter_by(community_id=community_id).all()
                                 ^^^^^^^^^^^^^^^
AttributeError: type object 'CommunityUser' has no attribute 'user'
2024-11-16 18:32:44,597 - app - ERROR - Internal Server Error: 500 Internal Server Error: The server encountered an internal error and was unable to complete your request. Either the server is overloaded or there is an error in the application.
