2024-11-16 18:16:38,564 - app - ERROR - Exception on /community/create [POST]
Traceback (most recent call last):
  File "/home/juanant/Desktop/RaboDeToro-hub-1/RaboDeToroHub1venv/lib/python3.12/site-packages/flask/app.py", line 1473, in wsgi_app
    response = self.full_dispatch_request()
               ^^^^^^^^^^^^^^^^^^^^^^^^^^^^
  File "/home/juanant/Desktop/RaboDeToro-hub-1/RaboDeToroHub1venv/lib/python3.12/site-packages/flask/app.py", line 882, in full_dispatch_request
    rv = self.handle_user_exception(e)
         ^^^^^^^^^^^^^^^^^^^^^^^^^^^^^
  File "/home/juanant/Desktop/RaboDeToro-hub-1/RaboDeToroHub1venv/lib/python3.12/site-packages/flask_restful/__init__.py", line 298, in error_router
    return original_handler(e)
           ^^^^^^^^^^^^^^^^^^^
  File "/home/juanant/Desktop/RaboDeToro-hub-1/RaboDeToroHub1venv/lib/python3.12/site-packages/flask/app.py", line 880, in full_dispatch_request
    rv = self.dispatch_request()
         ^^^^^^^^^^^^^^^^^^^^^^^
  File "/home/juanant/Desktop/RaboDeToro-hub-1/RaboDeToroHub1venv/lib/python3.12/site-packages/flask/app.py", line 865, in dispatch_request
    return self.ensure_sync(self.view_functions[rule.endpoint])(**view_args)  # type: ignore[no-any-return]
           ^^^^^^^^^^^^^^^^^^^^^^^^^^^^^^^^^^^^^^^^^^^^^^^^^^^^^^^^^^^^^^^^^
  File "/home/juanant/Desktop/RaboDeToro-hub-1/RaboDeToroHub1venv/lib/python3.12/site-packages/flask_login/utils.py", line 290, in decorated_view
    return current_app.ensure_sync(func)(*args, **kwargs)
           ^^^^^^^^^^^^^^^^^^^^^^^^^^^^^^^^^^^^^^^^^^^^^^
  File "/home/juanant/Desktop/RaboDeToro-hub-1/app/modules/community/routes.py", line 45, in create_community
    community = community_service.create(name=name, description=description,
                ^^^^^^^^^^^^^^^^^^^^^^^^^^^^^^^^^^^^^^^^^^^^^^^^^^^^^^^^^^^^
  File "/home/juanant/Desktop/RaboDeToro-hub-1/core/services/BaseService.py", line 9, in create
    return self.repository.create(**kwargs)
           ^^^^^^^^^^^^^^^^^^^^^^^^^^^^^^^^
  File "/home/juanant/Desktop/RaboDeToro-hub-1/core/repositories/BaseRepository.py", line 14, in create
    instance: T = self.model(**kwargs)
                  ^^^^^^^^^^^^^^^^^^^^
  File "<string>", line 4, in __init__
  File "/home/juanant/Desktop/RaboDeToro-hub-1/RaboDeToroHub1venv/lib/python3.12/site-packages/sqlalchemy/orm/state.py", line 571, in _initialize_instance
    with util.safe_reraise():
  File "/home/juanant/Desktop/RaboDeToro-hub-1/RaboDeToroHub1venv/lib/python3.12/site-packages/sqlalchemy/util/langhelpers.py", line 146, in __exit__
    raise exc_value.with_traceback(exc_tb)
  File "/home/juanant/Desktop/RaboDeToro-hub-1/RaboDeToroHub1venv/lib/python3.12/site-packages/sqlalchemy/orm/state.py", line 569, in _initialize_instance
    manager.original_init(*mixed[1:], **kwargs)
  File "/home/juanant/Desktop/RaboDeToro-hub-1/RaboDeToroHub1venv/lib/python3.12/site-packages/sqlalchemy/orm/decl_base.py", line 2167, in _declarative_constructor
    raise TypeError(
TypeError: 'owner' is an invalid keyword argument for Community
2024-11-16 18:16:38,569 - app - ERROR - Internal Server Error: 500 Internal Server Error: The server encountered an internal error and was unable to complete your request. Either the server is overloaded or there is an error in the application.
2024-11-16 18:17:27,617 - app - ERROR - Exception on /community/create [POST]
Traceback (most recent call last):
  File "/home/juanant/Desktop/RaboDeToro-hub-1/RaboDeToroHub1venv/lib/python3.12/site-packages/flask/app.py", line 1473, in wsgi_app
    response = self.full_dispatch_request()
               ^^^^^^^^^^^^^^^^^^^^^^^^^^^^
  File "/home/juanant/Desktop/RaboDeToro-hub-1/RaboDeToroHub1venv/lib/python3.12/site-packages/flask/app.py", line 882, in full_dispatch_request
    rv = self.handle_user_exception(e)
         ^^^^^^^^^^^^^^^^^^^^^^^^^^^^^
  File "/home/juanant/Desktop/RaboDeToro-hub-1/RaboDeToroHub1venv/lib/python3.12/site-packages/flask_restful/__init__.py", line 298, in error_router
    return original_handler(e)
           ^^^^^^^^^^^^^^^^^^^
  File "/home/juanant/Desktop/RaboDeToro-hub-1/RaboDeToroHub1venv/lib/python3.12/site-packages/flask/app.py", line 880, in full_dispatch_request
    rv = self.dispatch_request()
         ^^^^^^^^^^^^^^^^^^^^^^^
  File "/home/juanant/Desktop/RaboDeToro-hub-1/RaboDeToroHub1venv/lib/python3.12/site-packages/flask/app.py", line 865, in dispatch_request
    return self.ensure_sync(self.view_functions[rule.endpoint])(**view_args)  # type: ignore[no-any-return]
           ^^^^^^^^^^^^^^^^^^^^^^^^^^^^^^^^^^^^^^^^^^^^^^^^^^^^^^^^^^^^^^^^^
  File "/home/juanant/Desktop/RaboDeToro-hub-1/RaboDeToroHub1venv/lib/python3.12/site-packages/flask_login/utils.py", line 290, in decorated_view
    return current_app.ensure_sync(func)(*args, **kwargs)
           ^^^^^^^^^^^^^^^^^^^^^^^^^^^^^^^^^^^^^^^^^^^^^^
  File "/home/juanant/Desktop/RaboDeToro-hub-1/app/modules/community/routes.py", line 49, in create_community
    return redirect(url_for('community.get_community', community=community))
                    ^^^^^^^^^^^^^^^^^^^^^^^^^^^^^^^^^^^^^^^^^^^^^^^^^^^^^^^
  File "/home/juanant/Desktop/RaboDeToro-hub-1/RaboDeToroHub1venv/lib/python3.12/site-packages/flask/helpers.py", line 220, in url_for
    return current_app.url_for(
           ^^^^^^^^^^^^^^^^^^^^
  File "/home/juanant/Desktop/RaboDeToro-hub-1/RaboDeToroHub1venv/lib/python3.12/site-packages/flask/app.py", line 1084, in url_for
    return self.handle_url_build_error(error, endpoint, values)
           ^^^^^^^^^^^^^^^^^^^^^^^^^^^^^^^^^^^^^^^^^^^^^^^^^^^^
  File "/home/juanant/Desktop/RaboDeToro-hub-1/RaboDeToroHub1venv/lib/python3.12/site-packages/flask/app.py", line 1073, in url_for
    rv = url_adapter.build(  # type: ignore[union-attr]
         ^^^^^^^^^^^^^^^^^^^^^^^^^^^^^^^^^^^^^^^^^^^^^^
  File "/home/juanant/Desktop/RaboDeToro-hub-1/RaboDeToroHub1venv/lib/python3.12/site-packages/werkzeug/routing/map.py", line 924, in build
    raise BuildError(endpoint, values, method, self)
werkzeug.routing.exceptions.BuildError: Could not build url for endpoint 'community.get_community' with values ['community']. Did you forget to specify values ['community_id']?
2024-11-16 18:17:27,621 - app - ERROR - Internal Server Error: 500 Internal Server Error: The server encountered an internal error and was unable to complete your request. Either the server is overloaded or there is an error in the application.
2024-11-16 18:21:39,650 - app - ERROR - Exception on /community/create [POST]
Traceback (most recent call last):
  File "/home/juanant/Desktop/RaboDeToro-hub-1/RaboDeToroHub1venv/lib/python3.12/site-packages/flask/app.py", line 1473, in wsgi_app
    response = self.full_dispatch_request()
               ^^^^^^^^^^^^^^^^^^^^^^^^^^^^
  File "/home/juanant/Desktop/RaboDeToro-hub-1/RaboDeToroHub1venv/lib/python3.12/site-packages/flask/app.py", line 882, in full_dispatch_request
    rv = self.handle_user_exception(e)
         ^^^^^^^^^^^^^^^^^^^^^^^^^^^^^
  File "/home/juanant/Desktop/RaboDeToro-hub-1/RaboDeToroHub1venv/lib/python3.12/site-packages/flask_restful/__init__.py", line 298, in error_router
    return original_handler(e)
           ^^^^^^^^^^^^^^^^^^^
  File "/home/juanant/Desktop/RaboDeToro-hub-1/RaboDeToroHub1venv/lib/python3.12/site-packages/flask/app.py", line 880, in full_dispatch_request
    rv = self.dispatch_request()
         ^^^^^^^^^^^^^^^^^^^^^^^
  File "/home/juanant/Desktop/RaboDeToro-hub-1/RaboDeToroHub1venv/lib/python3.12/site-packages/flask/app.py", line 865, in dispatch_request
    return self.ensure_sync(self.view_functions[rule.endpoint])(**view_args)  # type: ignore[no-any-return]
           ^^^^^^^^^^^^^^^^^^^^^^^^^^^^^^^^^^^^^^^^^^^^^^^^^^^^^^^^^^^^^^^^^
  File "/home/juanant/Desktop/RaboDeToro-hub-1/RaboDeToroHub1venv/lib/python3.12/site-packages/flask_login/utils.py", line 290, in decorated_view
    return current_app.ensure_sync(func)(*args, **kwargs)
           ^^^^^^^^^^^^^^^^^^^^^^^^^^^^^^^^^^^^^^^^^^^^^^
  File "/home/juanant/Desktop/RaboDeToro-hub-1/app/modules/community/routes.py", line 48, in create_community
    community = community_service.create(name=name, description=description,
                ^^^^^^^^^^^^^^^^^^^^^^^^^^^^^^^^^^^^^^^^^^^^^^^^^^^^^^^^^^^^
  File "/home/juanant/Desktop/RaboDeToro-hub-1/core/services/BaseService.py", line 9, in create
    return self.repository.create(**kwargs)
           ^^^^^^^^^^^^^^^^^^^^^^^^^^^^^^^^
  File "/home/juanant/Desktop/RaboDeToro-hub-1/core/repositories/BaseRepository.py", line 14, in create
    instance: T = self.model(**kwargs)
                  ^^^^^^^^^^^^^^^^^^^^
  File "<string>", line 4, in __init__
  File "/home/juanant/Desktop/RaboDeToro-hub-1/RaboDeToroHub1venv/lib/python3.12/site-packages/sqlalchemy/orm/state.py", line 571, in _initialize_instance
    with util.safe_reraise():
  File "/home/juanant/Desktop/RaboDeToro-hub-1/RaboDeToroHub1venv/lib/python3.12/site-packages/sqlalchemy/util/langhelpers.py", line 146, in __exit__
    raise exc_value.with_traceback(exc_tb)
  File "/home/juanant/Desktop/RaboDeToro-hub-1/RaboDeToroHub1venv/lib/python3.12/site-packages/sqlalchemy/orm/state.py", line 569, in _initialize_instance
    manager.original_init(*mixed[1:], **kwargs)
  File "/home/juanant/Desktop/RaboDeToro-hub-1/RaboDeToroHub1venv/lib/python3.12/site-packages/sqlalchemy/orm/decl_base.py", line 2167, in _declarative_constructor
    raise TypeError(
TypeError: 'owner' is an invalid keyword argument for Community
2024-11-16 18:21:39,654 - app - ERROR - Internal Server Error: 500 Internal Server Error: The server encountered an internal error and was unable to complete your request. Either the server is overloaded or there is an error in the application.
