2024-11-13 02:24:50,781 - app - ERROR - Exception on /forgotPassword/forgot [POST]
Traceback (most recent call last):
  File "/home/josemorgado/Repo/RaboDeToro-hub-1/RaboDeToroHub1venv/lib/python3.12/site-packages/sqlalchemy/engine/base.py", line 1967, in _exec_single_context
    self.dialect.do_execute(
  File "/home/josemorgado/Repo/RaboDeToro-hub-1/RaboDeToroHub1venv/lib/python3.12/site-packages/sqlalchemy/engine/default.py", line 924, in do_execute
    cursor.execute(statement, parameters)
  File "/home/josemorgado/Repo/RaboDeToro-hub-1/RaboDeToroHub1venv/lib/python3.12/site-packages/pymysql/cursors.py", line 153, in execute
    result = self._query(query)
             ^^^^^^^^^^^^^^^^^^
  File "/home/josemorgado/Repo/RaboDeToro-hub-1/RaboDeToroHub1venv/lib/python3.12/site-packages/pymysql/cursors.py", line 322, in _query
    conn.query(q)
  File "/home/josemorgado/Repo/RaboDeToro-hub-1/RaboDeToroHub1venv/lib/python3.12/site-packages/pymysql/connections.py", line 563, in query
    self._affected_rows = self._read_query_result(unbuffered=unbuffered)
                          ^^^^^^^^^^^^^^^^^^^^^^^^^^^^^^^^^^^^^^^^^^^^^^
  File "/home/josemorgado/Repo/RaboDeToro-hub-1/RaboDeToroHub1venv/lib/python3.12/site-packages/pymysql/connections.py", line 825, in _read_query_result
    result.read()
  File "/home/josemorgado/Repo/RaboDeToro-hub-1/RaboDeToroHub1venv/lib/python3.12/site-packages/pymysql/connections.py", line 1199, in read
    first_packet = self.connection._read_packet()
                   ^^^^^^^^^^^^^^^^^^^^^^^^^^^^^^
  File "/home/josemorgado/Repo/RaboDeToro-hub-1/RaboDeToroHub1venv/lib/python3.12/site-packages/pymysql/connections.py", line 775, in _read_packet
    packet.raise_for_error()
  File "/home/josemorgado/Repo/RaboDeToro-hub-1/RaboDeToroHub1venv/lib/python3.12/site-packages/pymysql/protocol.py", line 219, in raise_for_error
    err.raise_mysql_exception(self._data)
  File "/home/josemorgado/Repo/RaboDeToro-hub-1/RaboDeToroHub1venv/lib/python3.12/site-packages/pymysql/err.py", line 150, in raise_mysql_exception
    raise errorclass(errno, errval)
pymysql.err.ProgrammingError: (1146, "Table 'uvlhubdb.token' doesn't exist")

The above exception was the direct cause of the following exception:

Traceback (most recent call last):
  File "/home/josemorgado/Repo/RaboDeToro-hub-1/RaboDeToroHub1venv/lib/python3.12/site-packages/flask/app.py", line 1473, in wsgi_app
    response = self.full_dispatch_request()
               ^^^^^^^^^^^^^^^^^^^^^^^^^^^^
  File "/home/josemorgado/Repo/RaboDeToro-hub-1/RaboDeToroHub1venv/lib/python3.12/site-packages/flask/app.py", line 882, in full_dispatch_request
    rv = self.handle_user_exception(e)
         ^^^^^^^^^^^^^^^^^^^^^^^^^^^^^
  File "/home/josemorgado/Repo/RaboDeToro-hub-1/RaboDeToroHub1venv/lib/python3.12/site-packages/flask_restful/__init__.py", line 298, in error_router
    return original_handler(e)
           ^^^^^^^^^^^^^^^^^^^
  File "/home/josemorgado/Repo/RaboDeToro-hub-1/RaboDeToroHub1venv/lib/python3.12/site-packages/flask/app.py", line 880, in full_dispatch_request
    rv = self.dispatch_request()
         ^^^^^^^^^^^^^^^^^^^^^^^
  File "/home/josemorgado/Repo/RaboDeToro-hub-1/RaboDeToroHub1venv/lib/python3.12/site-packages/flask/app.py", line 865, in dispatch_request
    return self.ensure_sync(self.view_functions[rule.endpoint])(**view_args)  # type: ignore[no-any-return]
           ^^^^^^^^^^^^^^^^^^^^^^^^^^^^^^^^^^^^^^^^^^^^^^^^^^^^^^^^^^^^^^^^^
  File "/home/josemorgado/Repo/RaboDeToro-hub-1/core/decorators/decorators.py", line 14, in decorated_function
    return f(*args, **kwargs)
           ^^^^^^^^^^^^^^^^^^
  File "/home/josemorgado/Repo/RaboDeToro-hub-1/app/modules/forgotPassword/routes.py", line 16, in forgot
    forgotPasswordService.addToken(token=token)
  File "/home/josemorgado/Repo/RaboDeToro-hub-1/app/modules/forgotPassword/services.py", line 41, in addToken
    db.session.commit()
  File "/home/josemorgado/Repo/RaboDeToro-hub-1/RaboDeToroHub1venv/lib/python3.12/site-packages/sqlalchemy/orm/scoping.py", line 597, in commit
    return self._proxied.commit()
           ^^^^^^^^^^^^^^^^^^^^^^
  File "/home/josemorgado/Repo/RaboDeToro-hub-1/RaboDeToroHub1venv/lib/python3.12/site-packages/sqlalchemy/orm/session.py", line 2017, in commit
    trans.commit(_to_root=True)
  File "<string>", line 2, in commit
  File "/home/josemorgado/Repo/RaboDeToro-hub-1/RaboDeToroHub1venv/lib/python3.12/site-packages/sqlalchemy/orm/state_changes.py", line 139, in _go
    ret_value = fn(self, *arg, **kw)
                ^^^^^^^^^^^^^^^^^^^^
  File "/home/josemorgado/Repo/RaboDeToro-hub-1/RaboDeToroHub1venv/lib/python3.12/site-packages/sqlalchemy/orm/session.py", line 1302, in commit
    self._prepare_impl()
  File "<string>", line 2, in _prepare_impl
  File "/home/josemorgado/Repo/RaboDeToro-hub-1/RaboDeToroHub1venv/lib/python3.12/site-packages/sqlalchemy/orm/state_changes.py", line 139, in _go
    ret_value = fn(self, *arg, **kw)
                ^^^^^^^^^^^^^^^^^^^^
  File "/home/josemorgado/Repo/RaboDeToro-hub-1/RaboDeToroHub1venv/lib/python3.12/site-packages/sqlalchemy/orm/session.py", line 1277, in _prepare_impl
    self.session.flush()
  File "/home/josemorgado/Repo/RaboDeToro-hub-1/RaboDeToroHub1venv/lib/python3.12/site-packages/sqlalchemy/orm/session.py", line 4341, in flush
    self._flush(objects)
  File "/home/josemorgado/Repo/RaboDeToro-hub-1/RaboDeToroHub1venv/lib/python3.12/site-packages/sqlalchemy/orm/session.py", line 4476, in _flush
    with util.safe_reraise():
  File "/home/josemorgado/Repo/RaboDeToro-hub-1/RaboDeToroHub1venv/lib/python3.12/site-packages/sqlalchemy/util/langhelpers.py", line 146, in __exit__
    raise exc_value.with_traceback(exc_tb)
  File "/home/josemorgado/Repo/RaboDeToro-hub-1/RaboDeToroHub1venv/lib/python3.12/site-packages/sqlalchemy/orm/session.py", line 4437, in _flush
    flush_context.execute()
  File "/home/josemorgado/Repo/RaboDeToro-hub-1/RaboDeToroHub1venv/lib/python3.12/site-packages/sqlalchemy/orm/unitofwork.py", line 466, in execute
    rec.execute(self)
  File "/home/josemorgado/Repo/RaboDeToro-hub-1/RaboDeToroHub1venv/lib/python3.12/site-packages/sqlalchemy/orm/unitofwork.py", line 642, in execute
    util.preloaded.orm_persistence.save_obj(
  File "/home/josemorgado/Repo/RaboDeToro-hub-1/RaboDeToroHub1venv/lib/python3.12/site-packages/sqlalchemy/orm/persistence.py", line 93, in save_obj
    _emit_insert_statements(
  File "/home/josemorgado/Repo/RaboDeToro-hub-1/RaboDeToroHub1venv/lib/python3.12/site-packages/sqlalchemy/orm/persistence.py", line 1233, in _emit_insert_statements
    result = connection.execute(
             ^^^^^^^^^^^^^^^^^^^
  File "/home/josemorgado/Repo/RaboDeToro-hub-1/RaboDeToroHub1venv/lib/python3.12/site-packages/sqlalchemy/engine/base.py", line 1418, in execute
    return meth(
           ^^^^^
  File "/home/josemorgado/Repo/RaboDeToro-hub-1/RaboDeToroHub1venv/lib/python3.12/site-packages/sqlalchemy/sql/elements.py", line 515, in _execute_on_connection
    return connection._execute_clauseelement(
           ^^^^^^^^^^^^^^^^^^^^^^^^^^^^^^^^^^
  File "/home/josemorgado/Repo/RaboDeToro-hub-1/RaboDeToroHub1venv/lib/python3.12/site-packages/sqlalchemy/engine/base.py", line 1640, in _execute_clauseelement
    ret = self._execute_context(
          ^^^^^^^^^^^^^^^^^^^^^^
  File "/home/josemorgado/Repo/RaboDeToro-hub-1/RaboDeToroHub1venv/lib/python3.12/site-packages/sqlalchemy/engine/base.py", line 1846, in _execute_context
    return self._exec_single_context(
           ^^^^^^^^^^^^^^^^^^^^^^^^^^
  File "/home/josemorgado/Repo/RaboDeToro-hub-1/RaboDeToroHub1venv/lib/python3.12/site-packages/sqlalchemy/engine/base.py", line 1986, in _exec_single_context
    self._handle_dbapi_exception(
  File "/home/josemorgado/Repo/RaboDeToro-hub-1/RaboDeToroHub1venv/lib/python3.12/site-packages/sqlalchemy/engine/base.py", line 2353, in _handle_dbapi_exception
    raise sqlalchemy_exception.with_traceback(exc_info[2]) from e
  File "/home/josemorgado/Repo/RaboDeToro-hub-1/RaboDeToroHub1venv/lib/python3.12/site-packages/sqlalchemy/engine/base.py", line 1967, in _exec_single_context
    self.dialect.do_execute(
  File "/home/josemorgado/Repo/RaboDeToro-hub-1/RaboDeToroHub1venv/lib/python3.12/site-packages/sqlalchemy/engine/default.py", line 924, in do_execute
    cursor.execute(statement, parameters)
  File "/home/josemorgado/Repo/RaboDeToro-hub-1/RaboDeToroHub1venv/lib/python3.12/site-packages/pymysql/cursors.py", line 153, in execute
    result = self._query(query)
             ^^^^^^^^^^^^^^^^^^
  File "/home/josemorgado/Repo/RaboDeToro-hub-1/RaboDeToroHub1venv/lib/python3.12/site-packages/pymysql/cursors.py", line 322, in _query
    conn.query(q)
  File "/home/josemorgado/Repo/RaboDeToro-hub-1/RaboDeToroHub1venv/lib/python3.12/site-packages/pymysql/connections.py", line 563, in query
    self._affected_rows = self._read_query_result(unbuffered=unbuffered)
                          ^^^^^^^^^^^^^^^^^^^^^^^^^^^^^^^^^^^^^^^^^^^^^^
  File "/home/josemorgado/Repo/RaboDeToro-hub-1/RaboDeToroHub1venv/lib/python3.12/site-packages/pymysql/connections.py", line 825, in _read_query_result
    result.read()
  File "/home/josemorgado/Repo/RaboDeToro-hub-1/RaboDeToroHub1venv/lib/python3.12/site-packages/pymysql/connections.py", line 1199, in read
    first_packet = self.connection._read_packet()
                   ^^^^^^^^^^^^^^^^^^^^^^^^^^^^^^
  File "/home/josemorgado/Repo/RaboDeToro-hub-1/RaboDeToroHub1venv/lib/python3.12/site-packages/pymysql/connections.py", line 775, in _read_packet
    packet.raise_for_error()
  File "/home/josemorgado/Repo/RaboDeToro-hub-1/RaboDeToroHub1venv/lib/python3.12/site-packages/pymysql/protocol.py", line 219, in raise_for_error
    err.raise_mysql_exception(self._data)
  File "/home/josemorgado/Repo/RaboDeToro-hub-1/RaboDeToroHub1venv/lib/python3.12/site-packages/pymysql/err.py", line 150, in raise_mysql_exception
    raise errorclass(errno, errval)
sqlalchemy.exc.ProgrammingError: (pymysql.err.ProgrammingError) (1146, "Table 'uvlhubdb.token' doesn't exist")
[SQL: INSERT INTO token (token, `usedTime`) VALUES (%(token)s, %(usedTime)s)]
[parameters: {'token': 'InVzZXIxQGV4YW1wbGUuY29tIg.ZzP_4g.5dd4A0OFpKB4LhCeLeGiovjvRas', 'usedTime': None}]
(Background on this error at: https://sqlalche.me/e/20/f405)
